Workbook

Sheet Índice
C3: Modelo de Valuación Financiera
C5: Southern Copper Corporacion
C7: Julio 14, 2025
M11: Equipo: Valuers B20
M12: Carlos Caballero Reyes
M13: Tatiana Rodas Espinoza

Sheet Supuestos
B2: SOUTHERN COPPER COORPORATION
B3: Julio 14, 2025
B4: Supuestos | G4: 2020 | H4: 2021 | I4: 2022 | J4: 2023 | K4: 2024 | L4: 2025 | M4: 2026 | N4: 2027 | O4: 2028 | P4: 2029 | Q4: 2030 | R4: 2031 | S4: 2032 | T4: 2033 | U4: 2034 | V4: 2035 | W4: 2036 | X4: 2037
B6: Supuestos de Industria y Macroeconomia | C6: [Unidad] | D6: Fuente
B8: Inflación EE,UU, | C8: % | D8: FED | G8: 1,3% | H8: 4,7% | I8: 8,0% | J8: 4,1% | K8: 2,6% | L8: 2,8% | M8: 2,4% | N8: 2,2% | O8: 2,1% | P8: 2,1% | Q8: =+P8 -> 2,1% | R8: =+Q8 -> 2,1% | S8: =+R8 -> 2,1% | T8: =+S8 -> 2,1% | U8: =+T8 -> 2,1% | V8: =+U8 -> 2,1% | W8: =+V8 -> 2,1% | X8: =+W8 -> 2,1%
B9: PBI Real de EE,UU, | C9: % | D9: FED | G9: -2,8% | H9: 6,0% | I9: 2,1% | J9: 1,6% | K9: 2,8% | L9: 1,1% | M9: 1,8% | N9: 2,1% | O9: 2,1% | P9: 2,1% | Q9: =+P9 -> 2,1% | R9: =+Q9 -> 2,1% | S9: =+R9 -> 2,1% | T9: =+S9 -> 2,1% | U9: =+T9 -> 2,1% | V9: =+U9 -> 2,1% | W9: =+V9 -> 2,1% | X9: =+W9 -> 2,1%
B10: Tasa de Impuesto efectivo | C10: % | D10: SCCO | G10: 0.4149 | H10: 0.3984 | I10: 0.3649 | J10: 0.379 | K10: 0.3659 | L10: =+$K$10 -> 0.3659 | M10: =+$K$10 -> 0.3659 | N10: =+$K$10 -> 0.3659 | O10: =+$K$10 -> 0.3659 | P10: =+$K$10 -> 0.3659 | Q10: =+$K$10 -> 0.3659 | R10: =+$K$10 -> 0.3659 | S10: =+$K$10 -> 0.3659 | ... X10: =+$K$10 -> 0.3659
B11: Tasa de variacion del precio promedio del cobre | C11: % | D11: LME | G11: 2,9% | H11: =+'Ventas proyectadas'!H73/'Ventas proyectadas'!G73-1 -> 0.51071429 | I11: =+'Ventas proyectadas'!I73/'Ventas proyectadas'!H73-1 -> -0.054373522 | J11: =+'Ventas proyectadas'!J73/'Ventas proyectadas'!I73-1 -> -0.0375 | K11: =+'Ventas proyectadas'!K73/'Ventas proyectadas'!J73-1 -> 0.077922078 | L11: =+'Ventas proyectadas'!L73/'Ventas proyectadas'!K73-1 -> 0.20481928 | M11: =+'Ventas proyectadas'!M73/'Ventas proyectadas'!L73-1 -> -0.199 | N11: =+'Ventas proyectadas'!N73/'Ventas proyectadas'!M73-1 -> 0.050145651 | O11: =+'Ventas proyectadas'!O73/'Ventas proyectadas'!N73-1 -> -0.00095766462 | ... X11: =+'Ventas proyectadas'!X73/'Ventas proyectadas'!W73-1 -> -0.0013009348
B12: Tasa de crecimiento de producción de cobre mundial | C12: % | D12: USGV | G12: 3,0% | H12: 1,9% | I12: 4,8% | J12: 2,7% | K12: 1,8% | L12: 2,4% | M12: 2,6% | N12: 2,9% | O12: 2,6% | P12: 3,4% | Q12: =+P12 -> 3,4% | R12: =+Q12 -> 3,4% | S12: =+R12 -> 3,4% | T12: =+S12 -> 3,4% | U12: =+T12 -> 3,4% | V12: =+U12 -> 3,4% | W12: =+V12 -> 3,4% | X12: =+W12 -> 3,4%
B13: Tasa de crecimiento del sector mineria en EE,UU, | C13: % | D13: Trading Economics | G13: -2,5% | H13: -8,8% | I13: -9,3% | J13: 33,6% | K13: 1,0% | L13: 2,3% | M13: 1,7% | N13: 2,7% | O13: 1,4% | P13: 3,5% | Q13: =+P13 -> 3,5% | R13: =+Q13 -> 3,5% | S13: =+R13 -> 3,5% | T13: =+S13 -> 3,5% | U13: =+T13 -> 3,5% | V13: =+U13 -> 3,5% | W13: =+V13 -> 3,5% | X13: =+W13 -> 3,5%
B15: Supuestos de Estado de Resultados
B17: A) Ingresos | C17: [Unidad]
B19: Ingresos | C19: Millones USD | G19: =+'Ventas proyectadas'!G7 -> 7984.9 | H19: =+'Ventas proyectadas'!H7 -> 10934.1 | I19: =+'Ventas proyectadas'!I7 -> 10047.9 | J19: =+'Ventas proyectadas'!J7 -> 9895.8 | K19: =+'Ventas proyectadas'!K7 -> 11433.4 | L19: =+'Ventas proyectadas'!L7 -> 13637.03 | M19: =+'Ventas proyectadas'!M7 -> 11737.677 | N19: =+'Ventas proyectadas'!N7 -> 13043.462 | ... X19: =+'Ventas proyectadas'!X7 -> 34288.491
B20: YoY | C20: % | G20: =+'Ventas proyectadas'!G8 -> -0.26971831 | H20: =+H19/G19-1 -> 0.36934714 | I20: =+I19/H19-1 -> -0.081049195 | J20: =+J19/I19-1 -> -0.015137491 | K20: =+K19/J19-1 -> 0.15537905 | L20: =+L19/K19-1 -> 0.19273618 | M20: =+M19/L19-1 -> -0.13927906 | N20: =+N19/M19-1 -> 0.11124726 | O20: =+O19/N19-1 -> 0.069481607 | ... X20: =+X19/W19-1 -> 0.015711431
B22: B) Costos | C22: [Unidad]
B24: Costos Totales | C24: Millones USD | G24: 3930 | H24: 3894 | I24: 4841.4 | J24: 4687.7 | K24: 4649.1 | L24: =+SUM(L26+L29+L32+L35+L38+L41) -> 6190.0969 | M24: =+SUM(M26+M29+M32+M35+M38+M41) -> 5327.9461 | N24: =+SUM(N26+N29+N32+N35+N38+N41) -> 5920.6655 | O24: =+SUM(O26+O29+O32+O35+O38+O41) -> 6332.0428 | P24: =+SUM(P26+P29+P32+P35+P38+P41) -> 6821.6872 | Q24: =+SUM(Q26+Q29+Q32+Q35+Q38+Q41) -> 7785.7569 | R24: =+SUM(R26+R29+R32+R35+R38+R41) -> 8036.3624 | S24: =+SUM(S26+S29+S32+S35+S38+S41) -> 14285.005 | ... X24: =+SUM(X26+X29+X32+X35+X38+X41) -> 15564.173
B26: Power | C26: Millones USD | I26: 808.51 | J26: 623.46 | K26: 511.4 | L26: =+L27*L$19 -> 855.48115 | M26: =+M27*M$19 -> 736.33054 | N26: =+N27*N$19 -> 818.24529 | O26: =+O27*O$19 -> 875.09829 | P26: =+P27*P$19 -> 942.76792 | Q26: =+Q27*Q$19 -> 1076.0039 | R26: =+R27*R$19 -> 1110.6379 | S26: =+S27*S$19 -> 1974.2102 | ... X26: =+X27*X$19 -> 2150.9932
B27: % de Ingresos | C27: % | I27: =+I26/I$19 -> 0.08046557 | J27: =+J26/J$19 -> 0.063002486 | K27: =+K26/K$19 -> 0.044728602 | L27: =+AVERAGE($I27:$K27) -> 0.062732219 | M27: =+AVERAGE($I27:$K27) -> 0.062732219 | N27: =+AVERAGE($I27:$K27) -> 0.062732219 | O27: =+AVERAGE($I27:$K27) -> 0.062732219 | P27: =+AVERAGE($I27:$K27) -> 0.062732219 | Q27: =+AVERAGE($I27:$K27) -> 0.062732219 | R27: =+AVERAGE($I27:$K27) -> 0.062732219 | S27: =+AVERAGE($I27:$K27) -> 0.062732219 | ... X27: =+AVERAGE($I27:$K27) -> 0.062732219
B29: Labor | C29: Millones USD | I29: 522.87 | J29: 543.77 | K29: 613.68 | L29: =+L30*L$19 -> 730.31584 | M29: =+M30*M$19 -> 628.59814 | N29: =+N30*N$19 -> 698.52796 | O29: =+O30*O$19 -> 747.06281 | P29: =+P30*P$19 -> 804.8317 | Q29: =+Q30*Q$19 -> 918.57393 | R29: =+R30*R$19 -> 948.14069 | S29: =+S30*S$19 -> 1685.3638 | ... X29: =+X30*X$19 -> 1836.2817
B30: % de Ingresos | C30: % | I30: =+I29/I$19 -> 0.052037739 | J30: =+J29/J$19 -> 0.054949575 | K30: =+K29/K$19 -> 0.053674323 | L30: =+AVERAGE($I30:$K30) -> 0.053553879 | M30: =+AVERAGE($I30:$K30) -> 0.053553879 | N30: =+AVERAGE($I30:$K30) -> 0.053553879 | O30: =+AVERAGE($I30:$K30) -> 0.053553879 | P30: =+AVERAGE($I30:$K30) -> 0.053553879 | Q30: =+AVERAGE($I30:$K30) -> 0.053553879 | R30: =+AVERAGE($I30:$K30) -> 0.053553879 | S30: =+AVERAGE($I30:$K30) -> 0.053553879 | ... X30: =+AVERAGE($I30:$K30) -> 0.053553879
B32: Fuel | C32: Millones USD | I32: 813.36 | J32: 735.97 | K32: 715.96 | L32: =+L33*L$19 -> 990.68593 | M32: =+M33*M$19 -> 852.70413 | N32: =+N33*N$19 -> 947.56512 | O32: =+O33*O$19 -> 1013.4035 | P32: =+P33*P$19 -> 1091.768 | Q32: =+Q33*Q$19 -> 1246.0612 | R32: =+R33*R$19 -> 1286.1691 | S32: =+S33*S$19 -> 2286.2249 | ... X32: =+X33*X$19 -> 2490.9475
B33: % de Ingresos | C33: % | I33: =+I32/I$19 -> 0.080948258 | J33: =+J32/J$19 -> 0.074371956 | K33: =+K32/K$19 -> 0.062620043 | L33: =+AVERAGE($I33:$K33) -> 0.072646752 | M33: =+AVERAGE($I33:$K33) -> 0.072646752 | N33: =+AVERAGE($I33:$K33) -> 0.072646752 | O33: =+AVERAGE($I33:$K33) -> 0.072646752 | P33: =+AVERAGE($I33:$K33) -> 0.072646752 | Q33: =+AVERAGE($I33:$K33) -> 0.072646752 | R33: =+AVERAGE($I33:$K33) -> 0.072646752 | S33: =+AVERAGE($I33:$K33) -> 0.072646752 | ... X33: =+AVERAGE($I33:$K33) -> 0.072646752
B35: Maintenance | C35: Millones USD | I35: 948.91 | J35: 1003.17 | K35: 1087.89 | L35: =+L36*L$19 -> 1322.6197 | M35: =+M36*M$19 -> 1138.4065 | N35: =+N36*N$19 -> 1265.0511 | O35: =+O36*O$19 -> 1352.9489 | P35: =+P36*P$19 -> 1457.5697 | Q35: =+Q36*Q$19 -> 1663.5597 | R35: =+R36*R$19 -> 1717.1058 | S35: =+S36*S$19 -> 3052.2348 | ... X35: =+X36*X$19 -> 3325.5507
B36: % de Ingresos | C36: % | I36: =+I35/I$19 -> 0.094438639 | J36: =+J35/J$19 -> 0.10137331 | K36: =+K35/K$19 -> 0.095150174 | L36: =+AVERAGE($I36:$K36) -> 0.096987374 | M36: =+AVERAGE($I36:$K36) -> 0.096987374 | N36: =+AVERAGE($I36:$K36) -> 0.096987374 | O36: =+AVERAGE($I36:$K36) -> 0.096987374 | P36: =+AVERAGE($I36:$K36) -> 0.096987374 | Q36: =+AVERAGE($I36:$K36) -> 0.096987374 | R36: =+AVERAGE($I36:$K36) -> 0.096987374 | S36: =+AVERAGE($I36:$K36) -> 0.096987374 | ... X36: =+AVERAGE($I36:$K36) -> 0.096987374
B38: Operating material | C38: Millones USD | I38: 973.12 | J38: 918.79 | K38: 883.33 | L38: =+L39*L$19 -> 1213.4833 | M38: =+M39*M$19 -> 1044.4705 | N38: =+N39*N$19 -> 1160.665 | O38: =+O39*O$19 -> 1241.3099 | P38: =+P39*P$19 -> 1337.2979 | Q38: =+Q39*Q$19 -> 1526.2905 | R38: =+R39*R$19 -> 1575.4183 | S38: =+S39*S$19 -> 2800.3787 | ... X38: =+X39*X$19 -> 3051.1419
B39: % de Inflación | C39: % | I39: =+I38/I$19 -> 0.096848098 | J39: =+J38/J$19 -> 0.09284646 | K39: =+K38/K$19 -> 0.077258733 | L39: =+AVERAGE($I39:$K39) -> 0.08898443 | M39: =+AVERAGE($I39:$K39) -> 0.08898443 | N39: =+AVERAGE($I39:$K39) -> 0.08898443 | O39: =+AVERAGE($I39:$K39) -> 0.08898443 | P39: =+AVERAGE($I39:$K39) -> 0.08898443 | Q39: =+AVERAGE($I39:$K39) -> 0.08898443 | R39: =+AVERAGE($I39:$K39) -> 0.08898443 | S39: =+AVERAGE($I39:$K39) -> 0.08898443 | ... X39: =+AVERAGE($I39:$K39) -> 0.08898443
B41: Others | C41: Millones USD | I41: 774.62 | J41: 862.54 | K41: 832.19 | L41: =+L42*L$19 -> 1077.511 | M41: =+M42*M$19 -> 927.43624 | N41: =+N42*N$19 -> 1030.611 | O41: =+O42*O$19 -> 1102.2195 | P41: =+P42*P$19 -> 1187.452 | Q41: =+Q42*Q$19 -> 1355.2677 | R41: =+R42*R$19 -> 1398.8906 | S41: =+S42*S$19 -> 2486.5926 | ... X41: =+X42*X$19 -> 2709.2575
C42: % | I42: =+I41/I$19 -> 0.077092726 | J42: =+J41/J$19 -> 0.08716223 | K42: =+K41/K$19 -> 0.072785873 | L42: =+AVERAGE($I42:$K42) -> 0.07901361 | M42: =+AVERAGE($I42:$K42) -> 0.07901361 | N42: =+AVERAGE($I42:$K42) -> 0.07901361 | O42: =+AVERAGE($I42:$K42) -> 0.07901361 | P42: =+AVERAGE($I42:$K42) -> 0.07901361 | Q42: =+AVERAGE($I42:$K42) -> 0.07901361 | R42: =+AVERAGE($I42:$K42) -> 0.07901361 | S42: =+AVERAGE($I42:$K42) -> 0.07901361 | ... X42: =+AVERAGE($I42:$K42) -> 0.07901361
B44: C) Opex
B46: Opex | C46: Millones USD | I46: =+I49 -> 125 | J46: =+J49 -> 127.2 | K46: =+K49 -> 130.5 | L46: =+L49 -> 173.13373 | M46: =+M49 -> 149.01983 | N46: =+N49 -> 165.59788 | O46: =+O49 -> 177.10388 | P46: =+P49 -> 190.79898 | ... X46: =+X49 -> 435.32166
B49: Selling, general and administrative (SGA) | C49: Millones USD | G49: =+G50*G19 -> 99.335433 | H49: =+H50*H19 -> 136.02469 | I49: 125 | J49: 127.2 | K49: 130.5 | L49: =+L50*L19 -> 173.13373 | M49: =+M50*M19 -> 149.01983 | N49: =+N50*N19 -> 165.59788 | O49: =+O50*O19 -> 177.10388 | P49: =+P50*P19 -> 190.79898 | Q49: =+Q50*Q19 -> 217.7635 | R49: =+R50*R19 -> 224.7728 | S49: =+S50*S19 -> 399.54403 | ... X49: =+X50*X19 -> 435.32166
B50: % de Ingresos | C50: % | G50: 0.01244041 | H50: 0.01244041 | I50: =+I49/$I$19 -> 0.01244041 | J50: =+J49/$I$19 -> 0.012659362 | K50: =+K49/$I$19 -> 0.012987788 | L50: =+AVERAGE($I$50:$K$50) -> 0.012695854 | M50: =+AVERAGE($I$50:$K$50) -> 0.012695854 | N50: =+AVERAGE($I$50:$K$50) -> 0.012695854 | O50: =+AVERAGE($I$50:$K$50) -> 0.012695854 | P50: =+AVERAGE($I$50:$K$50) -> 0.012695854 | Q50: =+AVERAGE($I$50:$K$50) -> 0.012695854 | R50: =+AVERAGE($I$50:$K$50) -> 0.012695854 | S50: =+AVERAGE($I$50:$K$50) -> 0.012695854 | ... X50: =+AVERAGE($I$50:$K$50) -> 0.012695854
B53: D) Capex, depreciación y amortización
B55: 1, Capex
B57: Capex
B59: Activos fijos sin contar depreciación | C59: Millones USD | G59: 18614 | H59: 19193 | I59: 19949 | J59: 20581 | K59: 21104 | L59: =+L61*L19 -> 25171.504 | M59: =+M61*M19 -> 21665.641 | N59: =+N61*N19 -> 24075.884 | O59: =+O61*O19 -> 25748.715 | P59: =+P61*P19 -> 27739.813 | Q59: =+Q61*Q19 -> 31660.121 | R59: =+R61*R19 -> 32679.186 | S59: =+S61*S19 -> 58088.762 | ... X59: =+X61*X19 -> 63290.388
B60: Incremento de activos | C60: Millones USD | G60: =+G59-17908 -> 706 | H60: =+H59-18614 -> 579 | I60: =+I59-H59 -> 756 | J60: =+J59-I59 -> 632 | K60: =+K59-J59 -> 523 | L60: =+L59-K59 -> 4067.5044 | M60: =+M59-L59 -> -3505.8634 | N60: =+N59-M59 -> 2410.2432 | O60: =+O59-N59 -> 1672.8311 | P60: =+P59-O59 -> 1991.0974 | ... X60: =+X59-W59 -> 979.00103
B61: % de ingresos | C61: % | G61: =+G59/G19 -> 2.33115 | H61: =+H59/H19 -> 1.7553342 | I61: =+I59/I19 -> 1.98539 | J61: =+J59/J19 -> 2.0797712 | K61: =+K59/K19 -> 1.8458201 | L61: 1.8458201 | M61: 1.8458201 | N61: 1.8458201 | O61: 1.8458201 | P61: 1.8458201 | Q61: 1.8458201 | R61: 1.8458201 | S61: 1.8458201 | T61: 1.8458201 | U61: 1.8458201 | V61: 1.8458201 | W61: 1.8458201 | X61: 1.8458201
B62: Intangibles sin contar amortización | C62: Millones USD | G62: 143 | H62: 138 | I62: 135 | J62: 130 | K62: 125 | L62: =+L19*L64 -> 170.48747 | M62: =+M19*M64 -> 143.08843 | N62: =+N19*N64 -> 154.89201 | O62: =+O19*O64 -> 170.03525 | P62: =+P19*P64 -> 181.61742 | Q62: =+Q19*Q64 -> 206.68051 | R62: =+R19*R64 -> 214.36368 | S62: =+S19*S64 -> 380.18935 | ... X62: =+X19*X64 -> 414.39598
B63: Incremento de intangibles | C63: Millones USD | G63: =+G62-148 -> -5 | H63: =+H62-G62 -> -5 | I63: =+I62-H62 -> -3 | J63: =+J62-I62 -> -5 | K63: =+K62-J62 -> -5 | L63: =+L62-K62 -> 45.487467 | M63: =+M62-L62 -> -27.399037 | N63: =+N62-M62 -> 11.80358 | O63: =+O62-N62 -> 15.143241 | ... X63: =+X62-W62 -> 6.4613883
...

Sheet Ventas proyectadas
B2: SOUTHERN COPPER COORPORATION
B3: Julio 14, 2025
B4: Ventas proyectadas | G4: 2020 | H4: 2021 | I4: 2022 | J4: 2023 | K4: 2024 | L4: 2025 | M4: 2026 | N4: 2027 | O4: 2028 | P4: 2029 | Q4: 2030 | R4: 2031 | S4: 2032 | T4: 2033 | U4: 2034 | V4: 2035 | W4: 2036 | X4: 2037
B6: Ventas | C6: [Unidad] | D6: Fuente
B7: Ingreso por ventas | C7: Millones USD | G7: 7984.9 | H7: 10934.1 | I7: 10047.9 | J7: 9895.8 | K7: 11433.4 | L7: =+(L12*L73+L35*L74+L50*L75+L60*L76)/1000 -> 13637.03 | M7: =+(M12*M73+M35*M74+M50*M75+M60*M76)/1000 -> 11737.677 | N7: =+(N12*N73+N35*N74+N50*N75+N60*N76)/1000 -> 13043.462 | O7: =+(O12*O73+O35*O74+O50*O75+O60*O76)/1000 -> 13949.742 | P7: =+(P12*P73+P35*P74+P50*P75+P60*P76)/1000 -> 15028.448 | Q7: =+(Q12*Q73+Q35*Q74+Q50*Q75+Q60*Q76)/1000 -> 17152.332 | R7: =+(R12*R73+R35*R74+R50*R75+R60*R76)/1000 -> 17704.426 | S7: =+(S12*S73+S35*S74+S50*S75+S60*S76)/1000 -> 31470.434 | ... X7: =+(X12*X73+X35*X74+X50*X75+X60*X76)/1000 -> 34288.491
B8: Growth Y/Y | C8: % | G8: =+(G7/10934)-1 -> -0.26971831 | H8: =+(H7/G7)-1 -> 0.36934714 | I8: =+(I7/H7)-1 -> -0.081049195 | J8: =+(J7/I7)-1 -> -0.015137491 | K8: =+(K7/J7)-1 -> 0.15537905 | L8: =+(L7/10934)-1 -> 0.24721327 | M8: =+(M7/L7)-1 -> -0.13927906 | N8: =+(N7/M7)-1 -> 0.11124726 | O8: =+(O7/N7)-1 -> 0.069481607 | P8: =+(P7/O7)-1 -> 0.077328031 | Q8: =+(Q7/10934)-1 -> 0.56871523 | R8: =+(R7/Q7)-1 -> 0.032187681 | S8: =+(S7/R7)-1 -> 0.77754615 | T8: =+(T7/S7)-1 -> 0.020541474 | U8: =+(U7/T7)-1 -> 0.016439845 | V8: =+(V7/10934)-1 -> 2.0359853 | W8: =+(W7/V7)-1 -> 0.016949298 | X8: =+(X7/W7)-1 -> 0.015711431
B10: Producción (Refinado) | C10: [Unidad] | D10: Fuente
B11: 1. Copper
B12: Copper (no refinado) | G12: =+SUM(G15:G21) -> 2207600 | H12: =+SUM(H15:H21) -> 2112500 | I12: =+SUM(I15:I21) -> 1972500 | J12: =+SUM(J15:J21) -> 2008400 | K12: =+SUM(K15:K21) -> 2147000 | L12: =+SUM(L15:L21) -> 2254350 | M12: =+SUM(M15:M21) -> 2321980.5 | N12: =+SUM(N15:N21) -> 2507738.9 | ... X12: =+SUM(X15:X21) -> 4461376.3
B13: Growth Y/Y | C13: % | G13: =+G12/2191000-1 -> 0.0075764491 | H13: =+H12/G12-1 -> -0.043078456 | I13: =+I12/H12-1 -> -0.066272189 | J13: =+J12/I12-1 -> 0.018200253 | K13: =+K12/J12-1 -> 0.069010157 | L13: 0.05 | M13: 0.03 | N13: 0.08 | O13: 0.08 | P13: 0.08 | Q13: 0.03 | R13: 0.03 | S13: 0.03 | T13: 0.03 | U13: 0.03 | V13: 0.03 | W13: 0.03 | X13: 0.03
B15: Toquepala | C15: miles de lb. | G15: 562400 | H15: 505700 | I15: 444200 | J15: 495800 | K15: 549600 | L15: =+K15*(1+L$24) -> 577080 | M15: =+L15*(1+M$24) -> 594392.4 | N15: =+M15*(1+N$24) -> 641943.79 | O15: =+N15*(1+O$24) -> 693299.3 | P15: =+O15*(1+P$24) -> 748763.24 | Q15: =+P15*(1+Q$24) -> 771226.14 | R15: =+Q15*(1+R$24) -> 794362.92 | S15: =+R15*(1+S$24) -> 818193.81 | ... X15: =+W15*(1+X$24) -> 948510.87
B16: Cuajone | C16: miles de lb. | G16: 371800 | H16: 372600 | I16: 309400 | J16: 329000 | K16: 363500 | L16: =+K16*(1+L$24) -> 381675 | M16: =+L16*(1+M$24) -> 393125.25 | N16: =+M16*(1+N$24) -> 424575.27 | O16: =+N16*(1+O$24) -> 458541.29 | P16: =+O16*(1+P$24) -> 495224.59 | Q16: =+P16*(1+Q$24) -> 510081.33 | R16: =+Q16*(1+R$24) -> 525383.77 | S16: =+R16*(1+S$24) -> 541145.29 | ... X16: =+W16*(1+X$24) -> 627335.7
B17: La Caridad | C17: miles de lb. | G17: 298800 | H17: 282400 | I17: 246500 | J17: 244300 | K17: 257900 | L17: =+K17*(1+L$24) -> 270795 | M17: =+L17*(1+M$24) -> 278918.85 | N17: =+M17*(1+N$24) -> 301232.36 | O17: =+N17*(1+O$24) -> 325330.95 | P17: =+O17*(1+P$24) -> 351357.42 | Q17: =+P17*(1+Q$24) -> 361898.15 | R17: =+Q17*(1+R$24) -> 372755.09 | S17: =+R17*(1+S$24) -> 383937.74 | ... X17: =+W17*(1+X$24) -> 445089.07
B18: Buenavista | C18: miles de lb. | G18: 951900 | H18: 932600 | I18: 952300 | J18: 918200 | K18: 954500 | L18: =+K18*(1+L$24) -> 1002225 | M18: =+L18*(1+M$24) -> 1032291.8 | N18: =+M18*(1+N$24) -> 1114875.1 | O18: =+N18*(1+O$24) -> 1204065.1 | P18: =+O18*(1+P$24) -> 1300390.3 | Q18: =+P18*(1+Q$24) -> 1339402 | R18: =+Q18*(1+R$24) -> 1379584.1 | S18: =+R18*(1+S$24) -> 1420971.6 | ... X18: =+W18*(1+X$24) -> 1647295.5
B19: IMMSA unit | C19: miles de lb. | G19: 22700 | H19: 19200 | I19: 20100 | J19: 21100 | K19: 21500 | L19: =+K19*(1+L$24) -> 22575 | M19: =+L19*(1+M$24) -> 23252.25 | N19: =+M19*(1+N$24) -> 25112.43 | O19: =+N19*(1+O$24) -> 27121.424 | P19: =+O19*(1+P$24) -> 29291.138 | Q19: =+P19*(1+Q$24) -> 30169.873 | R19: =+Q19*(1+R$24) -> 31074.969 | S19: =+R19*(1+S$24) -> 32007.218 | ... X19: =+W19*(1+X$24) -> 37105.138
B20: Proyecto Michiquillay | C20: miles de lb. | S20: 496040 | T20: 496040 | U20: 496040 | V20: 496040 | W20: 496040 | X20: 496040
B21: Proyecto Chancas | C21: miles de lb. | Q21: 260000 | R21: 260000 | S21: 260000 | T21: 260000 | U21: 260000 | V21: 260000 | W21: 260000 | X21: 260000
B23: Copper (refinado) | C23: miles de lb. | G23: =+SUM(G26:G32) -> 1491908 | H23: =+SUM(H26:H32) -> 1401719 | I23: =+SUM(I26:I32) -> 1495767 | J23: =+SUM(J26:J32) -> 1419817 | K23: =+SUM(K26:K32) -> 1403040 | L23: =+SUM(L26:L32) -> 1473192 | M23: =+SUM(M26:M32) -> 1517387.8 | N23: =+SUM(N26:N32) -> 1638778.8 | ... X23: =+SUM(X26:X32) -> 2421395
B24: Growth Y/Y | C24: % | G24: =+(G23/1412329)-1 -> 0.056345936 | H24: =+(H23/G23)-1 -> -0.060452119 | I24: =+(I23/H23)-1 -> 0.06709476 | J24: =+(J23/I23)-1 -> -0.050776625 | K24: =+(K23/J23)-1 -> -0.011816312 | L24: =+(L23/K23)-1 -> 0.05 | M24: =+(M23/L23)-1 -> 0.03 | N24: =+(N23/M23)-1 -> 0.08 | O24: =+(O23/N23)-1 -> 0.08 | ... X24: =+(X23/W23)-1 -> 0.03
B26: Peru open pit
B27: Cathode-Ilo | C27: miles de lb. | G27: 631118 | H27: 573583 | I27: 638741 | J27: 638589 | K27: 634707 | L27: =+K27*1.05 -> 666442.35 | M27: =+L27*(1.03) -> 686435.62 | N27: =+M27*(1.08) -> 741350.47 | O27: =+N27*(1.08) -> 800658.51 | P27: =+O27*(1.08) -> 864711.19 | Q27: =+P27*(1.03) -> 890652.52 | R27: =+Q27*(1.03) -> 917372.1 | S27: =+R27*(1.03) -> 944893.26 | T27: =+S27*(1.03) -> 973240.06 | U27: =+T27*(1.03) -> 1002437.3 | V27: =+U27*(1.03) -> 1032510.4 | W27: =+V27*(1.03) -> 1063485.7 | X27: =+W27*(1.03) -> 1095390.3
B28: SX-EW Toquepala | C28: miles de lb. | G28: 57342 | H28: 56777 | I28: 58315 | J28: 55672 | K28: 53165 | L28: =+K28*1.05 -> 55823.25 | M28: =+L28*(1.03) -> 57497.948 | N28: =+M28*(1.08) -> 62097.783 | O28: =+N28*(1.08) -> 67065.606 | P28: =+O28*(1.08) -> 72430.854 | Q28: =+P28*(1.03) -> 74603.78 | R28: =+Q28*(1.03) -> 76841.893 | S28: =+R28*(1.03) -> 79147.15 | T28: =+S28*(1.03) -> 81521.565 | U28: =+T28*(1.03) -> 83967.212 | V28: =+U28*(1.03) -> 86486.228 | W28: =+V28*(1.03) -> 89080.815 | X28: =+W28*(1.03) -> 91753.239
B29: Mexico open-pit | C29: miles de lb.
B30: Cathode-La Caridad | C30: miles de lb. | G30: 529997 | H30: 534980 | I30: 541600 | J30: 481841 | K30: 478701 | L30: =+K30*1.05 -> 502636.05 | M30: =+L30*(1.03) -> 517715.13 | N30: =+M30*(1.08) -> 559132.34 | O30: =+N30*(1.08) -> 603862.93 | P30: =+O30*(1.08) -> 652171.96 | Q30: =+P30*(1.03) -> 671737.12 | R30: =+Q30*(1.03) -> 691889.24 | S30: =+R30*(1.03) -> 712645.91 | T30: =+S30*(1.03) -> 734025.29 | U30: =+T30*(1.03) -> 756046.05 | V30: =+U30*(1.03) -> 778727.43 | W30: =+V30*(1.03) -> 802089.25 | X30: =+W30*(1.03) -> 826151.93
B31: SX-EW La Caridad | C31: miles de lb. | G31: 56981 | H31: 55942 | I31: 51449 | J31: 50691 | K31: 51257 | L31: =+K31*1.05 -> 53819.85 | M31: =+L31*(1.03) -> 55434.446 | N31: =+M31*(1.08) -> 59869.201 | O31: =+N31*(1.08) -> 64658.737 | P31: =+O31*(1.08) -> 69831.436 | Q31: =+P31*(1.03) -> 71926.379 | R31: =+Q31*(1.03) -> 74084.171 | S31: =+R31*(1.03) -> 76306.696 | T31: =+S31*(1.03) -> 78595.897 | U31: =+T31*(1.03) -> 80953.774 | V31: =+U31*(1.03) -> 83382.387 | W31: =+V31*(1.03) -> 85883.858 | X31: =+W31*(1.03) -> 88460.374
B32: SX-EW Lbuenavista | C32: miles de lb. | G32: 216470 | H32: 180437 | I32: 205662 | J32: 193024 | K32: 185210 | L32: =+K32*1.05 -> 194470.5 | M32: =+L32*(1.03) -> 200304.61 | N32: =+M32*(1.08) -> 216328.98 | O32: =+N32*(1.08) -> 233635.3 | P32: =+O32*(1.08) -> 252326.13 | Q32: =+P32*(1.03) -> 259895.91 | R32: =+Q32*(1.03) -> 267692.79 | S32: =+R32*(1.03) -> 275723.57 | T32: =+S32*(1.03) -> 283995.28 | U32: =+T32*(1.03) -> 292515.14 | V32: =+U32*(1.03) -> 301290.59 | W32: =+V32*(1.03) -> 310329.31 | X32: =+W32*(1.03) -> 319639.19
B34: 2. Silver
B35: Silver (no refinado) | C35: miles de oz. | G35: =+G38+G39 -> 21500 | H35: =+H38+H39 -> 19000 | I35: =+I38+I39 -> 18600 | J35: =+J38+J39 -> 18400 | K35: =+K38+K39 -> 21000 | L35: =+L38+L39 -> 21039.569 | M35: =+M38+M39 -> 21079.212 | N35: =+N38+N39 -> 21118.93 | ... X35: =+X38+X39 -> 517560.25
B36: Growth Y/Y | C36: % | G36: =+G35/(20300)-1 -> 0.0591133 | H36: =+H35/G35-1 -> -0.11627907 | I36: =+I35/H35-1 -> -0.021052632 | J36: =+J35/I35-1 -> -0.010752688 | K36: =+K35/J35-1 -> 0.14130435 | L36: =+L35/K35-1 -> 0.0018842174 | M36: =+M35/L35-1 -> 0.0018842174 | N36: =+N35/M35-1 -> 0.0018842174 | O36: =+O35/N35-1 -> 0.0018842174 | ... X36: =+X35/W35-1 -> 7.8204867e-05
B38: Silver | C38: miles de oz. | G38: 21500 | H38: 19000 | I38: 18600 | J38: 18400 | K38: 21000 | L38: =+K38*(1+L42) -> 21039.569 | M38: =+L38*(1+M42) -> 21079.212 | N38: =+M38*(1+N42) -> 21118.93 | O38: =+N38*(1+O42) -> 21158.722 | P38: =+O38*(1+P42) -> 21198.59 | Q38: =+P38*(1+Q42) -> 21238.533 | R38: =+Q38*(1+R42) -> 21278.551 | S38: =+R38*(1+S42) -> 21318.644 | ... X38: =+W38*(1+X42) -> 21520.247
B39: Nuevos proyectos | C39: miles de oz. | S39: 496040 | T39: 496040 | U39: 496040 | V39: 496040 | W39: 496040 | X39: 496040
B41: Silver (refinado) | C41: miles de oz. | G41: =+SUM(G44:G46) -> 13888 | H41: =+SUM(H44:H46) -> 13691 | I41: =+SUM(I44:I46) -> 14272 | J41: =+SUM(J44:J46) -> 10927 | K41: =+SUM(K44:K46) -> 11999 | L41: =+SUM(L44:L46) -> 12021.609 | M41: =+SUM(M44:M46) -> 12044.26 | N41: =+SUM(N44:N46) -> 12066.954 | ... X41: =+SUM(X44:X46) -> 12296.259
B42: Growth Y/Y | C42: % | G42: =+(G41/12588)-1 -> 0.10327296 | H42: =+(H41/G41)-1 -> -0.014184908 | I42: =+(I41/H41)-1 -> 0.042436637 | J42: =+(J41/I41)-1 -> -0.234375 | K42: =+(K41/J41)-1 -> 0.09810561 | L42: =+(L41/K41)-1 -> 0.0018842174 | M42: =+(M41/L41)-1 -> 0.0018842174 | N42: =+(N41/M41)-1 -> 0.0018842174 | O42: =+(O41/N41)-1 -> 0.0018842174 | ... X42: =+(X41/W41)-1 -> 0.0018842174
B44: Peru- Ilo | C44: miles de oz. | G44: 3967 | H44: 3985 | I44: 3741 | J44: 3526 | K44: 4070 | L44: =+K44*(1+AVERAGE($G$47:$K$47)/5) -> 4077.6688 | M44: =+L44*(1+AVERAGE($G$47:$K$47)/5) -> 4085.352 | N44: =+M44*(1+AVERAGE($G$47:$K$47)/5) -> 4093.0497 | O44: =+N44*(1+AVERAGE($G$47:$K$47)/5) -> 4100.7619 | P44: =+O44*(1+AVERAGE($G$47:$K$47)/5) -> 4108.4886 | Q44: =+P44*(1+AVERAGE($G$47:$K$47)/5) -> 4116.2299 | R44: =+Q44*(1+AVERAGE($G$47:$K$47)/5) -> 4123.9858 | S44: =+R44*(1+AVERAGE($G$47:$K$47)/5) -> 4131.7562 | ... X44: =+W44*(1+AVERAGE($G$47:$K$47)/5) -> 4170.8288
B45: Mexico-LaCaridad | C45: miles de oz. | G45: 8128 | H45: 7612 | I45: 8569 | J45: 7398 | K45: 7929 | L45: =+K45*(1+AVERAGE($G$47:$K$47)/5) -> 7943.94 | M45: =+L45*(1+AVERAGE($G$47:$K$47)/5) -> 7958.9081 | N45: =+M45*(1+AVERAGE($G$47:$K$47)/5) -> 7973.9044 | O45: =+N45*(1+AVERAGE($G$47:$K$47)/5) -> 7988.929 | P45: =+O45*(1+AVERAGE($G$47:$K$47)/5) -> 8003.9818 | Q45: =+P45*(1+AVERAGE($G$47:$K$47)/5) -> 8019.0631 | R45: =+Q45*(1+AVERAGE($G$47:$K$47)/5) -> 8034.1727 | S45: =+R45*(1+AVERAGE($G$47:$K$47)/5) -> 8049.3109 | ... X45: =+W45*(1+AVERAGE($G$47:$K$47)/5) -> 8125.4304
B46: IMMSA unit | C46: miles de oz. | G46: 1793 | H46: 2094 | I46: 1962 | J46: 3 | K46: 0 | L46: =+K46*(1+AVERAGE($G$47:$K$47)/5) -> 0 | M46: =+L46*(1+AVERAGE($G$47:$K$47)/5) -> 0 | N46: =+M46*(1+AVERAGE($G$47:$K$47)/5) -> 0 | O46: =+N46*(1+AVERAGE($G$47:$K$47)/5) -> 0 | P46: =+O46*(1+AVERAGE($G$47:$K$47)/5) -> 0 | Q46: =+P46*(1+AVERAGE($G$47:$K$47)/5) -> 0 | R46: =+Q46*(1+AVERAGE($G$47:$K$47)/5) -> 0 | S46: =+R46*(1+AVERAGE($G$47:$K$47)/5) -> 0 | ... X46: =+W46*(1+AVERAGE($G$47:$K$47)/5) -> 0
B47: prod silver as % de prod copper | G47: =+G38/G12 -> 0.0097390832 | H47: =+H38/H12 -> 0.0089940828 | I47: =+I38/I12 -> 0.0094296578 | J47: =+J38/J12 -> 0.0091615216 | K47: =+K38/K12 -> 0.0097810899
B49: 3. Molibdeno
B50: Molibdeno | C50: miles de lb. | G50: =+SUM(G53:G57) -> 66687 | H50: =+SUM(H53:H57) -> 66716 | I50: =+SUM(I53:I57) -> 57849 | J50: =+SUM(J53:J57) -> 59164 | K50: =+SUM(K53:K57) -> 63929 | L50: =+SUM(L53:L57) -> 65155.157 | M50: =+SUM(M53:M57) -> 66404.831 | N50: =+SUM(N53:N57) -> 67678.474 | ... X50: =+SUM(X53:X57) -> 98338.825
B51: Growth Y/Y | C51: % | G51: =+(G50/59272)-1 -> 0.12510123 | H51: =+(H50/G50)-1 -> 0.00043486737 | I51: =+(I50/H50)-1 -> -0.13290665 | J51: =+(J50/I50)-1 -> 0.022731594 | K51: =+(K50/J50)-1 -> 0.080538841 | L51: =+(L50/K50)-1 -> 0.019179976 | M51: =+(M50/L50)-1 -> 0.019179976 | N51: =+(N50/M50)-1 -> 0.019179976 | O51: =+(O50/N50)-1 -> 0.019179976 | ... X51: =+(X50/W50)-1 -> 0.015910618
...

Sheet Fin. Statement
B2: SOUTHERN COPPER COORPORATION
B3: Julio 14, 2025
B4: Estados Financieros | G4: 2020 | H4: 2021 | I4: 2022 | J4: 2023 | K4: 2024 | L4: 2025 | M4: 2026 | N4: 2027 | O4: 2028 | P4: 2029 | Q4: 2030 | R4: 2031 | S4: 2032 | T4: 2033 | U4: 2034 | V4: 2035 | W4: 2036 | X4: 2037
B6: Estado de Resultados (en millones de dólares) | C6: [Unidad] | D6: Fuente
B8: Ingresos operativos
B9: Total de ingresos operativos | G9: 7984.9 | H9: 10934.1 | I9: 10047.9 | J9: 9895.8 | K9: 11433.4
B11: Costos y Gastos Operativos
B12: Costos Operativos, excluyendo depreciación, amortización y acrecentamiento | G12: 3929.8 | H12: 3894.4 | I12: 4649.1 | J12: 4687.7 | K12: 4841.4
B13: Gastos generales y administrativos | G13: 126.2 | H13: 125.2 | I13: 125 | J13: 127.2 | K13: 130.5
B14: Depreciación, amortización y acrecentamiento | G14: 775.6 | H14: 806 | I14: 796.3 | J14: 833.6 | K14: 845.9
B15: Costos de desarrollo (exploración) | G15: 32.6 | H15: 43.4 | I15: 41.7 | J15: 55 | K15: 60.9
B16: Total de costos y gastos operativos | G16: 4864.2 | H16: 4869 | I16: 5612.1 | J16: 5703.5 | K16: 5878.7
B17: Utilidad operativa | G17: 3120.7 | H17: 6065.1 | I17: 4435.8 | J17: 4192.3 | K17: 5554.7
B20: Gastos por intereses | G20: -393.4 | H20: -387.9 | I20: -387.1 | J20: -376.3 | K20: -376.5
B21: Intereses capitalizados | G21: 26.8 | H21: 30.8 | I21: 47 | J21: 49.6 | K21: 42.4
B22: Otros ingresos (gastos) | G22: -27.5 | H22: -18.4 | I22: 117.1 | J22: 3.6 | K22: 5.5
B23: Ingresos por intereses | G23: 19.2 | H23: 7.2 | I23: 35 | J23: 86.6 | K23: 131.4
B24: Total de otros gastos netos | G24: -374.9 | H24: -368.3 | I24: -188 | J24: -236.5 | K24: -197.2
B25: Utilidad antes de impuestos | G25: 2745.8 | H25: 5696.8 | I25: 4247.8 | J25: 3955.8 | K25: 5357.5
... B36: Utilidad neta atribuible a SCCO | G36: 1570.4 | H36: 3397.1 | I36: 2638.5 | J36: 2425.2 | K36: 3376.9
B39: BALANCE GENERAL (en millones de dólares)
B41: ACTIVOS
B42: Activos Corrientes
B43: Efectivo y equivalentes de efectivo | G43: 2183.6 | H43: 3002 | I43: 2069.7 | J43: 1151.5 | K43: 3258.1
B44: Inversiones a corto plazo | G44: 410.8 | H44: 486.9 | I44: 208.3 | J44: 599.3 | K44: 245.3
B45: Cuentas por cobrar comerciales | G45: 1068.9 | H45: 1358.7 | I45: 1394.1 | J45: 1141.1 | K45: 1189.6
B46: Cuentas por cobrar otras (incluyendo partes relacionadas) | G46: 67.7 | H46: 87.9 | I46: 79.7 | J46: 87.2 | K46: 54.2
B47: Inventario | G47: 950.2 | H47: 972.9 | I47: 1013.9 | J47: 1016.9 | K47: 1048.9
B48: Impuestos prepagados | G48: 104.8 | H48: 197.7 | I48: 377.6 | J48: 395.4 | K48: 346.7
B49: Otros activos corrientes | G49: 29.2 | H49: 33.5 | I49: 44.4 | J49: 38.1 | K49: 31.7
B50: Total activo corriente | G50: 4815.2 | H50: 6139.6 | I50: 5187.7 | J50: 4429.5 | K50: 6174.5
B52: Activo No Corriente
B53: Desarrollo de propiedades y minas, neto | G53: 9458.7 | H53: 9464.4 | I53: 9596.6 | J53: 9782.9 | K53: 9883.3
B54: Reservas de mineral en plataformas de lixiviación | G54: 1125 | H54: 1097.6 | I54: 1064.3 | J54: 1121.7 | K54: 1145.8
B55: Activos intangibles, netos | G55: 143 | H55: 138.1 | I55: 134.7 | J55: 130.2 | K55: 124.6
B56: Activos por derecho de uso | G56: 979 | H56: 916.3 | I56: 851.4 | J56: 775.4 | K56: 739.5
B57: Impuesto sobre la renta diferido | G57: 230 | H57: 316.2 | I57: 237.3 | J57: 256.1 | K57: 310.6
B58: Inversión por el método de participación | G58: 114.3 | H58: 115.4 | I58: 110.8 | J58: 108.2 | K58: 111.9
B59: Otros activos no corrientes | G59: 81.3 | H59: 110 | I59: 94.6 | J59: 121.3 | K59: 223.5
B60: Total activo no corriente | G60: 12131.3 | H60: 12158 | I60: 12089.7 | J60: 12295.8 | K60: 12539.2
...

Sheet DCF
B2: SOUTHERN COPPER COORPORATION
B3: Julio 14, 2025
B4: Discount Cash Flow | G4: 2020 | H4: 2021 | I4: 2022 | J4: 2023 | K4: 2024 | L4: 2025 | M4: 2026 | N4: 2027 | O4: 2028 | P4: 2029 | Q4: 2030 | R4: 2031 | S4: 2032 | T4: 2033 | U4: 2034 | V4: 2035 | W4: 2036 | X4: 2037
B6: DCF | C6: [Unidad] | D6: Fuente
B8: Revenues | C8: Millones USD | L8: =+Supuestos!L19 -> 13637.03 | M8: =+Supuestos!M19 -> 11737.677 | N8: =+Supuestos!N19 -> 13043.462 | O8: =+Supuestos!O19 -> 13949.742 | P8: =+Supuestos!P19 -> 15028.448 | Q8: =+Supuestos!Q19 -> 17152.332 | R8: =+Supuestos!R19 -> 17704.426 | S8: =+Supuestos!S19 -> 31470.434 | ... X8: =+Supuestos!X19 -> 34288.491
B10: COGS | C10: Millones USD | L10: =+Supuestos!L24 -> 6190.0969 | M10: =+Supuestos!M24 -> 5327.9461 | N10: =+Supuestos!N24 -> 5920.6655 | O10: =+Supuestos!O24 -> 6332.0428 | P10: =+Supuestos!P24 -> 6821.6872 | Q10: =+Supuestos!Q24 -> 7785.7569 | R10: =+Supuestos!R24 -> 8036.3624 | S10: =+Supuestos!S24 -> 14285.005 | ... X10: =+Supuestos!X24 -> 15564.173
B11: Gross Profit | C11: Millones USD | L11: =+L8-L10 -> 7446.9329 | M11: =+M8-M10 -> 6409.7311 | N11: =+N8-N10 -> 7122.7961 | O11: =+O8-O10 -> 7617.6995 | P11: =+P8-P10 -> 8206.7612 | Q11: =+Q8-Q10 -> 9366.5754 | R11: =+R8-R10 -> 9668.0638 | S11: =+S8-S10 -> 17185.429 | ... X11: =+X8-X10 -> 18724.319
B12: Gross Mg. | C12: % | L12: =+L11/L8 -> 0.54608174 | M12: =+M11/M8 -> 0.54608174 | N12: =+N11/N8 -> 0.54608174 | O12: =+O11/O8 -> 0.54608174 | P12: =+P11/P8 -> 0.54608174 | Q12: =+Q11/Q8 -> 0.54608174 | R12: =+R11/R8 -> 0.54608174 | S12: =+S11/S8 -> 0.54608174 | ... X12: =+X11/X8 -> 0.54608174
B14: EBIT | C14: Millones USD | L14: =+L11-Supuestos!L49 -> 7273.7992 | M14: =+M11-Supuestos!M49 -> 6260.7113 | N14: =+N11-Supuestos!N49 -> 6957.1983 | O14: =+O11-Supuestos!O49 -> 7440.5956 | P14: =+P11-Supuestos!P49 -> 8015.9622 | Q14: =+Q11-Supuestos!Q49 -> 9148.8119 | R14: =+R11-Supuestos!R49 -> 9443.291 | S14: =+S11-Supuestos!S49 -> 16785.885 | ... X14: =+X11-Supuestos!X49 -> 18288.997
B15: EBIT Mg. | C15: % | L15: =+L14/L8 -> 0.53338588 | M15: =+M14/M8 -> 0.53338588 | N15: =+N14/N8 -> 0.53338588 | O15: =+O14/O8 -> 0.53338588 | P15: =+P14/P8 -> 0.53338588 | Q15: =+Q14/Q8 -> 0.53338588 | R15: =+R14/R8 -> 0.53338588 | S15: =+S14/S8 -> 0.53338588 | ... X15: =+X14/X8 -> 0.53338588
B17: Adjusted EBIT | C17: Millones USD | L17: =+L14 -> 7273.7992 | M17: =+M14 -> 6260.7113 | N17: =+N14 -> 6957.1983 | O17: =+O14 -> 7440.5956 | P17: =+P14 -> 8015.9622 | Q17: =+Q14 -> 9148.8119 | R17: =+R14 -> 9443.291 | S17: =+S14 -> 16785.885 | ... X17: =+X14 -> 18288.997
B18: Adjusted EBIT Mg. | C18: % | L18: =+L17/L8 -> 0.53338588 | M18: =+M17/M8 -> 0.53338588 | N18: =+N17/N8 -> 0.53338588 | O18: =+O17/O8 -> 0.53338588 | P18: =+P17/P8 -> 0.53338588 | Q18: =+Q17/Q8 -> 0.53338588 | R18: =+R17/R8 -> 0.53338588 | S18: =+S17/S8 -> 0.53338588 | ... X18: =+X17/X8 -> 0.53338588
B20: Taxes | C20: % | D20: 0.3659 | L20: =+$D$20*L17 -> 2661.4831 | M20: =+$D$20*M17 -> 2290.7943 | N20: =+$D$20*N17 -> 2545.6388 | O20: =+$D$20*O17 -> 2722.5139 | P20: =+$D$20*P17 -> 2933.0406 | Q20: =+$D$20*Q17 -> 3347.5503 | R20: =+$D$20*R17 -> 3455.3002 | S20: =+$D$20*S17 -> 6141.9555 | ... X20: =+$D$20*X17 -> 6691.9441
B21: NOPAT | C21: Millones USD | L21: =+L17-L20 -> 4612.3161 | M21: =+M17-M20 -> 3969.917 | N21: =+N17-N20 -> 4411.5594 | O21: =+O17-O20 -> 4718.0817 | P21: =+P17-P20 -> 5082.9216 | Q21: =+Q17-Q20 -> 5801.2616 | R21: =+R17-R20 -> 5987.9908 | S21: =+S17-S20 -> 10643.93 | ... X21: =+X17-X20 -> 11597.053
B24: Depreciation & Amortization | C24: Millones USD | L24: =+Supuestos!L74 -> 762.78818 | M24: =+Supuestos!M74 -> 656.54776 | N24: =+Supuestos!N74 -> 729.5869 | O24: =+Supuestos!O74 -> 780.27977 | P24: =+Supuestos!P74 -> 840.61727 | Q24: =+Supuestos!Q74 -> 959.41687 | R24: =+Supuestos!R74 -> 990.29827 | S24: =+Supuestos!S74 -> 1760.3009 | ... X24: =+Supuestos!X74 -> 1917.9291
B25: +/- Var. Working capital | C25: Millones USD | L25: =+WK!M30 -> 548.94416 | M25: =+WK!N30 -> -310.09705 | N25: =+WK!O30 -> 213.18836 | O25: =+WK!P30 -> 147.96355 | P25: =+WK!Q30 -> 176.11451 | Q25: =+WK!R30 -> 346.75506 | R25: =+WK!S30 -> 90.137372 | S25: =+WK!T30 -> 2247.5018 | ... X25: =+WK!Y30 -> 86.593597
B26: Capex | C26: Millones USD | L26: =+-'OPEX-CAPEX'!N42 -> -2382.8441 | M26: =+-'OPEX-CAPEX'!O42 -> -1684.6347 | N26: =+-'OPEX-CAPEX'!P42 -> -2006.2407 | O26: =+-'OPEX-CAPEX'!Q42 -> -3931.89 | P26: =+-'OPEX-CAPEX'!R42 -> -1044.129 | Q26: =+-'OPEX-CAPEX'!S42 -> -25417.259 | R26: =+-'OPEX-CAPEX'!T42 -> -1359.0544 | S26: =+-'OPEX-CAPEX'!U42 -> -982.35282 | ... X26: =+-'OPEX-CAPEX'!Z42 -> 0
B27: Free Cash Flows | C27: Millones USD | L27: =+L21+L24+L25+L26 -> 3541.2043 | M27: =+M21+M24+M25+M26 -> 2631.733 | N27: =+N21+N24+N25+N26 -> 3348.094 | O27: =+O21+O24+O25+O26 -> 1714.435 | P27: =+P21+P24+P25+P26 -> 5055.5244 | Q27: =+Q21+Q24+Q25+Q26 -> -18309.825 | R27: =+R21+R24+R25+R26 -> 5709.372 | S27: =+S21+S24+S25+S26 -> 13669.38 | ... X27: =+X21+X24+X25+X26 -> 13601.576
B28: Terminal Value | C28: Millones USD | X28: =+X27/(C41-C40) -> 223783.09
B31: Periods | K31: 0 | L31: 1 | M31: 2 | N31: 3 | O31: 4 | P31: 5 | Q31: 6 | R31: 7 | S31: 8 | T31: 9 | U31: 10 | V31: 11 | W31: 12 | X31: 13
B32: Discount factor | C32: % | L32: =1/(1+$C$41)^L31 -> 0.916775 | M32: =1/(1+$C$41)^M31 -> 0.84047641 | N32: =1/(1+$C$41)^N31 -> 0.77052776 | O32: =1/(1+$C$41)^O31 -> 0.70640059 | P32: =1/(1+$C$41)^P31 -> 0.6476104 | Q32: =1/(1+$C$41)^Q31 -> 0.59371303 | R32: =1/(1+$C$41)^R31 -> 0.54430127 | S32: =1/(1+$C$41)^S31 -> 0.49900179 | ... X32: =1/(1+$C$41)^X31 -> 0.32315875
B34: Discounted Cash Flows | C34: Millones USD | L34: =+L32*L27 -> 3246.4876 | M34: =+M32*M27 -> 2211.9095 | N34: =+N32*N27 -> 2579.7994 | O34: =+O32*O27 -> 1211.0779 | P34: =+P32*P27 -> 3274.0102 | Q34: =+Q32*Q27 -> -10870.782 | R34: =+R32*R27 -> 3107.6184 | S34: =+S32*S27 -> 6821.045 | ... X34: =+X32*X27 -> 4395.4683
B35: Discounted Terminal Value | C35: Millones USD | X35: =+X28*X32 -> 72317.465
B37: Valuation | C37: Valor
B39: Shares | C39: 884596086
B40: Growth (g) | C40: 0.03
B41: WACC | C41: =+WACC!E20 -> 0.090780176
B44: SOUTHERN COPPER COORPORATION | C44: USD M | E44: %
B45: Discounted Cash Flows | C45: =+SUM(L34:X34) -> 35751.411 | E45: =+C45/$C$47 -> 0.33082061
B46: Discounted Terminal Value | C46: =+X35 -> 72317.465 | E46: =+C46/$C$47 -> 0.66917939
B47: Enterprise Value (Jul, 14, 2025) | C47: =+C45+C46 -> 108068.88 | E47: =+C47/$C$47 -> 1
B48: Cash and equivalents | C48: =+'Fin. Statement'!K43+'Fin. Statement'!K44 -> 3503.4
B49: Debt | C49: =(583.1+7384.6) -> 7967.7
B50: Equity Value (Jul, 14, 2025) | C50: =+C47+C48-C49 -> 103604.58 | E50: 1
B51: Valor fundamental | C51: =+C50*1000000/C39 -> 117.12077 | E51: =+C51/$C$52 -> 1.171442
B52: Valor de acción | C52: 99.98 | E52: =+C52/$C$52 -> 1
B53: Resultado | E53: =+E51-E52 -> 0.17144201 | F53: Upside

Sheet WACC
B2: SOUTHERN COPPER COORPORATION
B3: Julio 14, 2025
B4: Costo promedio ponderado del Capital (WACC)
B6: CAPM | E6: 10 años | F6: Source | G6: Source
B7: Risk free (Rf) | E7: 0.0449 | F7: U.S. Department of the Treasury del Tesoro-USA - 30 años
B8: Market Risk Premium ( E(Rm)-Rf) | E8: 0.046 | F8: Damodaran
B9: Leveraged Beta (β) | E9: =+E10*(1+(1-E18)*E11) -> 1.0895771 | F9: Cálculo
B10: Unleveraged Beta | E10: 1.02 | F10: Damodaran
B11: Deuda/Equity | E11: =+E12/E13 -> 0.10757422 | F11: SCCO
B12: Deuda | E12: =583.1+7384.6 -> 7967.7
B13: Equity | E13: 74067
B15: Riesgo País
B16: Ke = Rf + β(E(Rm)- Rf) + Rp | E16: =+E7+E9*E8 -> 0.095020545
B17: Kd before taxes | E17: 0.081 | F17: Costo de deuda corporativa - Largo Plazo
B18: Effective tax rate | E18: 0.3659
B19: Kd after taxes | E19: =+E17*(1-E18) -> 0.0513621
B20: WACC | E20: =+E16*E13/(E13+E12) +E19*E12/(E13+E12) -> 0.090780176
B22: Análisis de Sensibilidad
B23: Variación = | C23: 0.005 | E23: g = | F23: =DCF!C40 -> 0.03 | G23: WACC | H23: P.O. | I23: =+DCF!C51 -> 117.12077
B26: =+I23 -> 117.12077 | C26: =+D26-$C$23 -> 0.075780176 | D26: =+E26-$C$23 -> 0.080780176 | E26: =+F26-$C$23 -> 0.085780176 | F26: =+E20 -> 0.090780176 | G26: =+F26+$C$23 -> 0.095780176 | H26: =+G26+$C$23 -> 0.10078018 | I26: =+H26+$C$23 -> 0.10578018
B27: =+B28-$C$23 -> 0.015 | C27: 170.55996 | D27: 232.33513 | E27: 278.75209 | F27: 278.75209 | G27: 232.33513 | H27: 170.55996 | I27: 117.12077
B28: =+B29-$C$23 -> 0.02 | C28: 170.55996 | D28: 232.33513 | E28: 278.75209 | F28: 278.75209 | G28: 232.33513 | H28: 170.55996 | I28: 117.12077
B29: =+B30-$C$23 -> 0.025 | C29: 170.55996 | D29: 232.33513 | E29: 278.75209 | F29: 278.75209 | G29: 232.33513 | H29: 170.55996 | I29: 117.12077
B30: =+F23 -> 0.03 | C30: 170.55996 | D30: 232.33513 | E30: 278.75209 | F30: 278.75209 | G30: 232.33513 | H30: 170.55996 | I30: 117.12077
B31: =+B30+$C$23 -> 0.035 | C31: 170.55996 | D31: 232.33513 | E31: 278.75209 | F31: 278.75209 | G31: 232.33513 | H31: 170.55996 | I31: 117.12077
B32: =+B31+$C$23 -> 0.04 | C32: 170.55996 | D32: 232.33513 | E32: 278.75209 | F32: 278.75209 | G32: 232.33513 | H32: 170.55996 | I32: 117.12077
B33: =+B32+$C$23 -> 0.045 | C33: 170.55996 | D33: 232.33513 | E33: 278.75209 | F33: 278.75209 | G33: 232.33513 | H33: 170.55996 | I33: 117.12077

Sheet WK
B2: SOUTHERN COPPER COORPORATION
B3: Julio 14, 2025
B4: Estados Financieros | H4: 2020 | I4: 2021 | J4: 2022 | K4: 2023 | L4: 2024 | M4: 2025 | N4: 2026 | O4: 2027 | P4: 2028 | Q4: 2029 | R4: 2030 | S4: 2031 | T4: 2032 | U4: 2033 | V4: 2034 | W4: 2035 | X4: 2036 | Y4: 2037
B6: Working capital | C6: [Unidad] | D6: Fuente
B8: Total Revenues | H8: =+Supuestos!G19 -> 7984.9 | I8: =+Supuestos!H19 -> 10934.1 | J8: =+Supuestos!I19 -> 10047.9 | K8: =+Supuestos!J19 -> 9895.8 | L8: =+Supuestos!K19 -> 11433.4 | M8: =+Supuestos!L19 -> 13637.03 | N8: =+Supuestos!M19 -> 11737.677 | O8: =+Supuestos!N19 -> 13043.462 | ... Y8: =+Supuestos!X19 -> 34288.491
B9: Total Costs | C9: Millones USD | H9: =+Supuestos!G24 -> 3930 | I9: =+Supuestos!H24 -> 3894 | J9: =+Supuestos!I24 -> 4841.4 | K9: =+Supuestos!J24 -> 4687.7 | L9: =+Supuestos!K24 -> 4649.1 | M9: =+Supuestos!L24 -> 6190.0969 | N9: =+Supuestos!M24 -> 5327.9461 | O9: =+Supuestos!N24 -> 5920.6655 | ... Y9: =+Supuestos!X24 -> 15564.173
B11: Total Current assets
B12: Trade accounts receivable, net | C12: Millones USD | H12: =+'Fin. Statement'!G45+'Fin. Statement'!G46 -> 1136.6 | I12: =+'Fin. Statement'!H45+'Fin. Statement'!H46 -> 1446.6 | J12: =+'Fin. Statement'!I45+'Fin. Statement'!I46 -> 1473.8 | K12: =+'Fin. Statement'!J45+'Fin. Statement'!J46 -> 1228.3 | L12: =+'Fin. Statement'!K45+'Fin. Statement'!K46 -> 1243.8 | M12: =+M8*M13 -> 1725.4812 | N12: =+N8*N13 -> 1485.1578 | O12: =+O8*O13 -> 1650.3775 | P12: =+P8*P13 -> 1765.0484 | Q12: =+Q8*Q13 -> 1901.5361 | R12: =+R8*R13 -> 2170.2693 | S12: =+S8*S13 -> 2240.1252 | T12: =+T8*T13 -> 3981.9259 | ... Y12: =+Y8*Y13 -> 4338.4922
B13: as % of Income | C13: % | H13: =+H12/H8 -> 0.14234367 | I13: =+I12/I8 -> 0.1323017 | J13: =+J12/J8 -> 0.14667742 | K13: =+K12/K8 -> 0.12412337 | L13: =+L12/L8 -> 0.10878654 | M13: =+AVERAGE($J$13:$L$13) -> 0.12652911 | N13: =+AVERAGE($J$13:$L$13) -> 0.12652911 | O13: =+AVERAGE($J$13:$L$13) -> 0.12652911 | P13: =+AVERAGE($J$13:$L$13) -> 0.12652911 | Q13: =+AVERAGE($J$13:$L$13) -> 0.12652911 | R13: =+AVERAGE($J$13:$L$13) -> 0.12652911 | S13: =+AVERAGE($J$13:$L$13) -> 0.12652911 | T13: =+AVERAGE($J$13:$L$13) -> 0.12652911 | ... Y13: =+AVERAGE($J$13:$L$13) -> 0.12652911
B14: Inventories, net | C14: Millones USD | H14: =+'Fin. Statement'!G47 -> 950.2 | I14: =+'Fin. Statement'!H47 -> 972.9 | J14: =+'Fin. Statement'!I47 -> 1013.9 | K14: =+'Fin. Statement'!J47 -> 1016.9 | L14: =+'Fin. Statement'!K47 -> 1048.9 | M14: =+M15*M8 -> 1342.8266 | N14: =+N15*N8 -> 1155.799 | O14: =+O15*O8 -> 1284.3784 | P14: =+P15*P8 -> 1373.6191 | Q14: =+Q15*Q8 -> 1479.8384 | R14: =+R15*R8 -> 1688.9754 | S14: =+S15*S8 -> 1743.3396 | T14: =+T15*T8 -> 3098.8666 | ... Y14: =+Y15*Y8 -> 3376.3582
B15: as % of Income | C15: % | H15: =+H14/H8 -> 0.11899961 | I15: =+I14/I8 -> 0.088978517 | J15: =+J14/J8 -> 0.10090666 | K15: =+K14/K8 -> 0.10276077 | L15: =+L14/L8 -> 0.09173999 | M15: =+AVERAGE($J$15:$L$15) -> 0.098469138 | N15: =+AVERAGE($J$15:$L$15) -> 0.098469138 | O15: =+AVERAGE($J$15:$L$15) -> 0.098469138 | P15: =+AVERAGE($J$15:$L$15) -> 0.098469138 | Q15: =+AVERAGE($J$15:$L$15) -> 0.098469138 | R15: =+AVERAGE($J$15:$L$15) -> 0.098469138 | S15: =+AVERAGE($J$15:$L$15) -> 0.098469138 | T15: =+AVERAGE($J$15:$L$15) -> 0.098469138 | ... Y15: =+AVERAGE($J$15:$L$15) -> 0.098469138
B17: Total Current liabilities
B18: Accounts payable to related parties | C18: Millones USD | H18: =+'Fin. Statement'!G67 -> 594.6 | I18: =+'Fin. Statement'!H67 -> 591.9 | J18: =+'Fin. Statement'!I67 -> 657.6 | K18: =+'Fin. Statement'!J67 -> 652.6 | L18: =+'Fin. Statement'!K67 -> 615.2 | M18: =+M19*M8 -> 841.86362 | N18: =+N19*N8 -> 724.60964 | O18: =+O19*O8 -> 805.22048 | P18: =+P19*P8 -> 861.16849 | Q18: =+Q19*Q8 -> 927.76096 | R18: =+R19*R8 -> 1058.8761 | S18: =+S19*S8 -> 1092.9588 | T18: =+T19*T8 -> 1942.7848 | ... Y18: =+Y19*Y8 -> 2116.7537
B19: as % of Income | C19: % | H19: =+H18/H8 -> 0.074465554 | I19: =+I18/I8 -> 0.054133399 | J19: =+J18/J8 -> 0.065446511 | K19: =+K18/K8 -> 0.06594717 | L19: =+L18/L8 -> 0.053807266 | M19: =+AVERAGE($J$19:$L$19) -> 0.061733649 | N19: =+AVERAGE($J$19:$L$19) -> 0.061733649 | O19: =+AVERAGE($J$19:$L$19) -> 0.061733649 | P19: =+AVERAGE($J$19:$L$19) -> 0.061733649 | Q19: =+AVERAGE($J$19:$L$19) -> 0.061733649 | R19: =+AVERAGE($J$19:$L$19) -> 0.061733649 | S19: =+AVERAGE($J$19:$L$19) -> 0.061733649 | T19: =+AVERAGE($J$19:$L$19) -> 0.061733649 | ... Y19: =+AVERAGE($J$19:$L$19) -> 0.061733649
B21: Days -Total Current assets
B22: Trade accounts receivable, net | C22: Days | E22: 365 | H22: =INT(H12/H8*$E$22) -> 51 | I22: =INT(I12/I8*$E$22) -> 48 | J22: =INT(J12/J8*$E$22) -> 53 | K22: =INT(K12/K8*$E$22) -> 45 | L22: =INT(L12/L8*$E$22) -> 39 | M22: =INT(M12/M8*$E$22) -> 46 | N22: =INT(N12/N8*$E$22) -> 46 | O22: =INT(O12/O8*$E$22) -> 46 | ... Y22: =INT(Y12/Y8*$E$22) -> 46
B23: Inventories, net | C23: Days | E23: 365 | H23: =+INT(H14/H9*$E$23) -> 88 | I23: =+INT(I14/I9*$E$23) -> 91 | J23: =+INT(J14/J9*$E$23) -> 76 | K23: =+INT(K14/K9*$E$23) -> 79 | L23: =+INT(L14/L9*$E$23) -> 82 | M23: =+INT(M14/M9*$E$23) -> 79 | N23: =+INT(N14/N9*$E$23) -> 79 | O23: =+INT(O14/O9*$E$23) -> 79 | ... Y23: =+INT(Y14/Y9*$E$23) -> 79
B25: Days -Total Current liabilities
B26: Accounts payable to related parties | C26: Days | E26: 365 | H26: =+INT(H18/H8*$E$26) -> 27 | I26: =+INT(I18/I8*$E$26) -> 19 | J26: =+INT(J18/J8*$E$26) -> 23 | K26: =+INT(K18/K8*$E$26) -> 24 | L26: =+INT(L18/L8*$E$26) -> 19 | M26: =+INT(M18/M8*$E$26) -> 22 | N26: =+INT(N18/N8*$E$26) -> 22 | O26: =+INT(O18/O8*$E$26) -> 22 | ... Y26: =+INT(Y18/Y8*$E$26) -> 22
B28: Operating Working Capital
B29: Working capital | C29: Millones USD | H29: =+H12+H14-H18 -> 1492.2 | I29: =+I12+I14-I18 -> 1827.6 | J29: =+J12+J14-J18 -> 1830.1 | K29: =+K12+K14-K18 -> 1592.6 | L29: =+L12+L14-L18 -> 1677.5 | M29: =+M12+M14-M18 -> 2226.4442 | N29: =+N12+N14-N18 -> 1916.3471 | O29: =+O12+O14-O18 -> 2129.5355 | ... Y29: =+Y12+Y14-Y18 -> 5598.0967
B30: Var. WK | C30: Millones USD | H30: - | I30: =+I29-H29 -> 335.4 | J30: =+J29-I29 -> 2.5 | K30: =+K29-J29 -> -237.5 | L30: =+L29-K29 -> 84.9 | M30: =+M29-L29 -> 548.94416 | N30: =+N29-M29 -> -310.09705 | O30: =+O29-N29 -> 213.18836 | P30: =+P29-O29 -> 147.96355 | ... Y30: =+Y29-X29 -> 86.593597
B33: Inventarios = (PMI/365)*Costos
B34: Cuentas por cobrar= (PMC/365)*Ingresos
B35: Cuentas por pagar = (PMP/365)*Ingresos
B36: PMI=(Inventarios/Costos)*365
B37: PMC=(Cuentas por cobrar/Ingresos)*365
B38: PMP=(Cuentas por pagar/Ingresos)*365

Sheet OPEX-CAPEX
B2: SOUTHERN COPPER COORPORATION
B3: Julio 14, 2025
B4: Estados Financieros | G4: 2020 | H4: 2021 | I4: 2022 | J4: 2023 | K4: 2024 | L4: 2025 | M4: 2026 | N4: 2027 | O4: 2028 | P4: 2029 | Q4: 2030 | R4: 2031 | S4: 2032 | T4: 2033 | U4: 2034 | V4: 2035 | W4: 2036 | X4: 2037
B6: Costos | C6: [Unidad] | D6: Fuente
B8: A) Costos | C8: [Unidad]
B10: =+Supuestos!B26 -> Power | C10: Millones USD | I10: =+Supuestos!I26 -> 808.51 | J10: =+Supuestos!J26 -> 623.46 | K10: =+Supuestos!K26 -> 511.4 | L10: =+Supuestos!L26 -> 855.48115 | M10: =+Supuestos!M26 -> 736.33054 | N10: =+Supuestos!N26 -> 818.24529 | O10: =+Supuestos!O26 -> 875.09829 | P10: =+Supuestos!P26 -> 942.76792 | ... X10: =+Supuestos!X26 -> 2150.9932
B11: =+Supuestos!B29 -> Labor | C11: Millones USD | I11: =+Supuestos!I29 -> 522.87 | J11: =+Supuestos!J29 -> 543.77 | K11: =+Supuestos!K29 -> 613.68 | L11: =+Supuestos!L29 -> 730.31584 | M11: =+Supuestos!M29 -> 628.59814 | N11: =+Supuestos!N29 -> 698.52796 | O11: =+Supuestos!O29 -> 747.06281 | P11: =+Supuestos!P29 -> 804.8317 | ... X11: =+Supuestos!X29 -> 1836.2817
B12: =+Supuestos!B32 -> Fuel | C12: Millones USD | I12: =+Supuestos!I32 -> 813.36 | J12: =+Supuestos!J32 -> 735.97 | K12: =+Supuestos!K32 -> 715.96 | L12: =+Supuestos!L32 -> 990.68593 | M12: =+Supuestos!M32 -> 852.70413 | N12: =+Supuestos!N32 -> 947.56512 | O12: =+Supuestos!O32 -> 1013.4035 | P12: =+Supuestos!P32 -> 1091.768 | ... X12: =+Supuestos!X32 -> 2490.9475
B13: =+Supuestos!B35 -> Maintenance | C13: Millones USD | I13: =+Supuestos!I35 -> 948.91 | J13: =+Supuestos!J35 -> 1003.17 | K13: =+Supuestos!K35 -> 1087.89 | L13: =+Supuestos!L35 -> 1322.6197 | M13: =+Supuestos!M35 -> 1138.4065 | N13: =+Supuestos!N35 -> 1265.0511 | O13: =+Supuestos!O35 -> 1352.9489 | P13: =+Supuestos!P35 -> 1457.5697 | ... X13: =+Supuestos!X35 -> 3325.5507
B14: =+Supuestos!B38 -> Operating material | C14: Millones USD | I14: =+Supuestos!I38 -> 973.12 | J14: =+Supuestos!J38 -> 918.79 | K14: =+Supuestos!K38 -> 883.33 | L14: =+Supuestos!L38 -> 1213.4833 | M14: =+Supuestos!M38 -> 1044.4705 | N14: =+Supuestos!N38 -> 1160.665 | O14: =+Supuestos!O38 -> 1241.3099 | P14: =+Supuestos!P38 -> 1337.2979 | ... X14: =+Supuestos!X38 -> 3051.1419
B15: =+Supuestos!B41 -> Others | C15: Millones USD | I15: =+Supuestos!I41 -> 774.62 | J15: =+Supuestos!J41 -> 862.54 | K15: =+Supuestos!K41 -> 832.19 | L15: =+Supuestos!L41 -> 1077.511 | M15: =+Supuestos!M41 -> 927.43624 | N15: =+Supuestos!N41 -> 1030.611 | O15: =+Supuestos!O41 -> 1102.2195 | P15: =+Supuestos!P41 -> 1187.452 | ... X15: =+Supuestos!X41 -> 2709.2575
B16: Costos Totales | C16: Millones USD | I16: =+Supuestos!I24 -> 4841.4 | J16: =+Supuestos!J24 -> 4687.7 | K16: =+Supuestos!K24 -> 4649.1 | L16: =+Supuestos!L24 -> 6190.0969 | M16: =+Supuestos!M24 -> 5327.9461 | N16: =+Supuestos!N24 -> 5920.6655 | O16: =+Supuestos!O24 -> 6332.0428 | P16: =+Supuestos!P24 -> 6821.6872 | ... X16: =+Supuestos!X24 -> 15564.173
B18: Opex | C18: [Unidad] | D18: Fuente
B20: B) Opex | C20: [Unidad]
B22: =+Supuestos!B49 -> Selling, general and administrative (SGA) | C22: =+Supuestos!C49 -> Millones USD | I22: =+Supuestos!I49 -> 125 | J22: =+Supuestos!J49 -> 127.2 | K22: =+Supuestos!K49 -> 130.5 | L22: =+Supuestos!L49 -> 173.13373 | M22: =+Supuestos!M49 -> 149.01983 | N22: =+Supuestos!N49 -> 165.59788 | O22: =+Supuestos!O49 -> 177.10388 | P22: =+Supuestos!P49 -> 190.79898 | ... X22: =+Supuestos!X49 -> 435.32166
B23: Opex | I23: =+I22 -> 125 | J23: =+J22 -> 127.2 | K23: =+K22 -> 130.5 | L23: =+L22 -> 173.13373 | M23: =+M22 -> 149.01983 | N23: =+N22 -> 165.59788 | O23: =+O22 -> 177.10388 | P23: =+P22 -> 190.79898 | ... X23: =+X22 -> 435.32166
B25: C) Cash cost | C25: [Unidad]
B27: Total operating cash cost before by product revenues | G27: =+((E16/1000)-('Ventas proyectadas'!G7-'Ventas proyectadas'!G12*'Ventas proyectadas'!G73))/('Ventas proyectadas'!G12) -> 2.796383 | H27: =+((F16/1000)-('Ventas proyectadas'!H7-'Ventas proyectadas'!H12*'Ventas proyectadas'!H73))/('Ventas proyectadas'!H12) -> 4.2248241 | I27: =+((G16/1000)-('Ventas proyectadas'!I7-'Ventas proyectadas'!I12*'Ventas proyectadas'!I73))/('Ventas proyectadas'!I12) -> 3.994906 | J27: =+((H16/1000)-('Ventas proyectadas'!J7-'Ventas proyectadas'!J12*'Ventas proyectadas'!J73))/('Ventas proyectadas'!J12) -> 3.8450728 | K27: =+((I16/1000)-('Ventas proyectadas'!K7-'Ventas proyectadas'!K12*'Ventas proyectadas'!K73))/('Ventas proyectadas'!K12) -> 4.144677 | L27: =+((J16/1000)-('Ventas proyectadas'!L7-'Ventas proyectadas'!L12*'Ventas proyectadas'!L73))/('Ventas proyectadas'!L12) -> 4.9939529 | M27: =+((K16/1000)-('Ventas proyectadas'!M7-'Ventas proyectadas'!M12*'Ventas proyectadas'!M73))/('Ventas proyectadas'!M12) -> 3.999947 | N27: =+((L16/1000)-('Ventas proyectadas'!N7-'Ventas proyectadas'!N12*'Ventas proyectadas'!N73))/('Ventas proyectadas'!N12) -> 4.2006345 | ... V27: =+((T16/1000)-('Ventas proyectadas'!V7-'Ventas proyectadas'!V12*'Ventas proyectadas'!V73))/('Ventas proyectadas'!V12) -> 4.2541486
B28: Total by product revenues
B29: Total operating cash cost net by product revenues
B30: Total pounds of copper produced
B31: Operating cash cost per pound before by product revenues
B35: Capex | C35: [Unidad] | D35: Fuente
B37: B) Capex | C37: [Unidad]
B39: Capex
B40: Activos fijos | C40: Millones USD | I40: =+Supuestos!I60 -> 756 | J40: =+Supuestos!J60 -> 632 | K40: =+Supuestos!K60 -> 523 | L40: =+Supuestos!L60 -> 4067.5044 | M40: =+Supuestos!M60 -> -3505.8634 | N40: =+Supuestos!N60 -> 2410.2432 | O40: =+Supuestos!O60 -> 1672.8311 | P40: =+Supuestos!P60 -> 1991.0974 | ... X40: =+Supuestos!X60 -> 979.00103
B41: Intangible | C41: Millones USD | I41: =+Supuestos!H63 -> -5 | J41: =+Supuestos!I63 -> -3 | K41: =+Supuestos!J63 -> -5 | L41: =+Supuestos!K63 -> -5 | M41: =+Supuestos!L63 -> 45.487467 | N41: =+Supuestos!M63 -> -27.399037 | O41: =+Supuestos!N63 -> 11.80358 | P41: =+Supuestos!O63 -> 15.143241 | ... X41: =+Supuestos!W63 -> 6.8255862
B42: Total Capex | C42: Millones USD | I42: =+I40+I41 -> 751 | J42: =+J40+J41 -> 629 | K42: =+K40+K41 -> 518 | L42: =+L40+L41 -> 4062.5044 | M42: =+M40+M41 -> -3460.376 | N42: =+N40+N41 -> 2382.8441 | O42: =+O40+O41 -> 1684.6347 | P42: =+P40+P41 -> 2006.2407 | ... X42: =+X40+X41 -> 985.82661
B43: as % of Income | I43: =+I42/Supuestos!I19 -> 0.074741986 | J43: =+J42/Supuestos!J19 -> 0.063562319 | K43: =+K42/Supuestos!K19 -> 0.045305858 | L43: =+L42/Supuestos!L19 -> 0.29790243 | M43: =+M42/Supuestos!M19 -> -0.29480926 | N43: =+N42/Supuestos!N19 -> 0.18268495 | O43: =+O42/Supuestos!O19 -> 0.12076458 | P43: =+P42/Supuestos!P19 -> 0.1334962 | ... X43: =+X42/Supuestos!X19 -> 0.028750947
B45: Depreciación
B46: Depreciación acumulada | C46: Millones USD | I46: =+Supuestos!G73 -> 8177 | J46: =+Supuestos!H73 -> 8812 | K46: =+Supuestos!I73 -> 9501 | L46: =+Supuestos!J73 -> 10003 | M46: =+Supuestos!K73 -> 10481 | N46: =+Supuestos!L73 -> 11243.788 | O46: =+Supuestos!M73 -> 11900.336 | P46: =+Supuestos!N73 -> 12629.923 | ... X46: =+Supuestos!V73 -> 23440.08
B47: Depreciacion | C47: Millones USD | I47: =+Supuestos!G74 -> 686 | J47: =+Supuestos!H74 -> 635 | K47: =+Supuestos!I74 -> 689 | L47: =+Supuestos!J74 -> 502 | M47: =+Supuestos!K74 -> 478 | N47: =+Supuestos!L74 -> 762.78818 | O47: =+Supuestos!M74 -> 656.54776 | P47: =+Supuestos!N74 -> 729.5869 | ... X47: =+Supuestos!V74 -> 1856.7905
